Workbook

Sheet Dashboard
B2: Project Management Dashboard
B3: Source data: "Project Management Data" | Live formulas — refresh automatically when source data changes
B5: TOTAL PROJECTS | D5: TOTAL TASKS | F5: AVG PROGRESS | H5: COMPLETED TASKS
B6: =SUMPRODUCT(1/COUNTIF('Project Management Data'!$B$7:$B$52,'Project Management Data'!$B$7:$B$52)) -> 15 | D6: =COUNTA('Project Management Data'!$B$7:$B$52) -> 46 | F6: =AVERAGE('Project Management Data'!$H$7:$H$52) -> 0.36891304 | H6: =COUNTIF('Project Management Data'!$H$7:$H$52,1) -> 9
B9: NOT STARTED TASKS | D9: OVERDUE TASKS | F9: TOTAL EFFORT (DAYS) | H9: AVG TASK DURATION
B10: =COUNTIF('Project Management Data'!$H$7:$H$52,0) -> 22 | D10: =SUMPRODUCT(('Project Management Data'!$G$7:$G$52<TODAY())*('Project Management Data'!$H$7:$H$52<1)) -> 37 | F10: =SUM('Project Management Data'!$F$7:$F$52) -> 1218 | H10: =AVERAGE('Project Management Data'!$F$7:$F$52) -> 26.478261
B13: Project Breakdown
B14: Project | C14: Task Count | D14: Avg Progress | E14: Total Effort (Days)
B15: Marketing | C15: =COUNTIF('Project Management Data'!$B$7:$B$52,$B15) -> 4 | D15: =AVERAGEIF('Project Management Data'!$B$7:$B$52,$B15,'Project Management Data'!$H$7:$H$52) -> 0.5575 | E15: =SUMIF('Project Management Data'!$B$7:$B$52,$B15,'Project Management Data'!$F$7:$F$52) -> 74
B16: Product Dev | C16: =COUNTIF('Project Management Data'!$B$7:$B$52,$B16) -> 3 | D16: =AVERAGEIF('Project Management Data'!$B$7:$B$52,$B16,'Project Management Data'!$H$7:$H$52) -> 0.59333333 | E16: =SUMIF('Project Management Data'!$B$7:$B$52,$B16,'Project Management Data'!$F$7:$F$52) -> 53
B17: Customer Svc | C17: =COUNTIF('Project Management Data'!$B$7:$B$52,$B17) -> 3 | D17: =AVERAGEIF('Project Management Data'!$B$7:$B$52,$B17,'Project Management Data'!$H$7:$H$52) -> 0.66666667 | E17: =SUMIF('Project Management Data'!$B$7:$B$52,$B17,'Project Management Data'!$F$7:$F$52) -> 77
B18: Financial | C18: =COUNTIF('Project Management Data'!$B$7:$B$52,$B18) -> 3 | D18: =AVERAGEIF('Project Management Data'!$B$7:$B$52,$B18,'Project Management Data'!$H$7:$H$52) -> 0.62666667 | E18: =SUMIF('Project Management Data'!$B$7:$B$52,$B18,'Project Management Data'!$F$7:$F$52) -> 68
B19: Research | C19: =COUNTIF('Project Management Data'!$B$7:$B$52,$B19) -> 3 | D19: =AVERAGEIF('Project Management Data'!$B$7:$B$52,$B19,'Project Management Data'!$H$7:$H$52) -> 0.16666667 | E19: =SUMIF('Project Management Data'!$B$7:$B$52,$B19,'Project Management Data'!$F$7:$F$52) -> 82
B20: Development | C20: =COUNTIF('Project Management Data'!$B$7:$B$52,$B20) -> 3 | D20: =AVERAGEIF('Project Management Data'!$B$7:$B$52,$B20,'Project Management Data'!$H$7:$H$52) -> 0.33333333 | E20: =SUMIF('Project Management Data'!$B$7:$B$52,$B20,'Project Management Data'!$F$7:$F$52) -> 100
B21: Production | C21: =COUNTIF('Project Management Data'!$B$7:$B$52,$B21) -> 3 | D21: =AVERAGEIF('Project Management Data'!$B$7:$B$52,$B21,'Project Management Data'!$H$7:$H$52) -> 0.1 | E21: =SUMIF('Project Management Data'!$B$7:$B$52,$B21,'Project Management Data'!$F$7:$F$52) -> 96
B22: Sales | C22: =COUNTIF('Project Management Data'!$B$7:$B$52,$B22) -> 3 | D22: =AVERAGEIF('Project Management Data'!$B$7:$B$52,$B22,'Project Management Data'!$H$7:$H$52) -> 0.49333333 | E22: =SUMIF('Project Management Data'!$B$7:$B$52,$B22,'Project Management Data'!$F$7:$F$52) -> 115
B23: Support | C23: =COUNTIF('Project Management Data'!$B$7:$B$52,$B23) -> 3 | D23: =AVERAGEIF('Project Management Data'!$B$7:$B$52,$B23,'Project Management Data'!$H$7:$H$52) -> 0.66666667 | E23: =SUMIF('Project Management Data'!$B$7:$B$52,$B23,'Project Management Data'!$F$7:$F$52) -> 78
B24: Operations | C24: =COUNTIF('Project Management Data'!$B$7:$B$52,$B24) -> 3 | D24: =AVERAGEIF('Project Management Data'!$B$7:$B$52,$B24,'Project Management Data'!$H$7:$H$52) -> 0.13333333 | E24: =SUMIF('Project Management Data'!$B$7:$B$52,$B24,'Project Management Data'!$F$7:$F$52) -> 75
B25: Consulting | C25: =COUNTIF('Project Management Data'!$B$7:$B$52,$B25) -> 3 | D25: =AVERAGEIF('Project Management Data'!$B$7:$B$52,$B25,'Project Management Data'!$H$7:$H$52) -> 0.2 | E25: =SUMIF('Project Management Data'!$B$7:$B$52,$B25,'Project Management Data'!$F$7:$F$52) -> 92
B26: Training | C26: =COUNTIF('Project Management Data'!$B$7:$B$52,$B26) -> 3 | D26: =AVERAGEIF('Project Management Data'!$B$7:$B$52,$B26,'Project Management Data'!$H$7:$H$52) -> 0.26666667 | E26: =SUMIF('Project Management Data'!$B$7:$B$52,$B26,'Project Management Data'!$F$7:$F$52) -> 79
... B29: Engineering | C29: =COUNTIF('Project Management Data'!$B$7:$B$52,$B29) -> 3 | D29: =AVERAGEIF('Project Management Data'!$B$7:$B$52,$B29,'Project Management Data'!$H$7:$H$52) -> 0.066666667 | E29: =SUMIF('Project Management Data'!$B$7:$B$52,$B29,'Project Management Data'!$F$7:$F$52) -> 74
B31: Task Status
B32: Status | C32: Count
B33: Completed | C33: =COUNTIF('Project Management Data'!$H$7:$H$52,1) -> 9
B34: In Progress | C34: =SUMPRODUCT(('Project Management Data'!$H$7:$H$52>0)*('Project Management Data'!$H$7:$H$52<1)) -> 15
B35: Not Started | C35: =COUNTIF('Project Management Data'!$H$7:$H$52,0) -> 22
B37: Task Timeline (Gantt)
B38: Task | C38: Start Date | D38: Duration (Days)
B39: ='Project Management Data'!C7 -> Market Research | C39: ='Project Management Data'!E7 -> 45292 | D39: ='Project Management Data'!F7 -> 13
B40: ='Project Management Data'!C32 -> Technical Support | C40: ='Project Management Data'!E32 -> 45292 | D40: ='Project Management Data'!F32 -> 25
B41: ='Project Management Data'!C11 -> Prototype Development | C41: ='Project Management Data'!E11 -> 45293 | D41: ='Project Management Data'!F11 -> 18
B42: ='Project Management Data'!C20 -> Market Trends Analysis | C42: ='Project Management Data'!E20 -> 45293 | D42: ='Project Management Data'!F20 -> 23
B43: ='Project Management Data'!C23 -> Software Development | C43: ='Project Management Data'!E23 -> 45293 | D43: ='Project Management Data'!F23 -> 36
B44: ='Project Management Data'!C38 -> Strategic Planning | C44: ='Project Management Data'!E38 -> 45293 | D44: ='Project Management Data'!F38 -> 35
B45: ='Project Management Data'!C50 -> Product Design | C45: ='Project Management Data'!E50 -> 45293 | D45: ='Project Management Data'!F50 -> 25
B46: ='Project Management Data'!C26 -> Manufacturing | C46: ='Project Management Data'!E26 -> 45294 | D46: ='Project Management Data'!F26 -> 47
B47: ='Project Management Data'!C29 -> Lead Generation | C47: ='Project Management Data'!E29 -> 45294 | D47: ='Project Management Data'!F29 -> 60
B48: ='Project Management Data'!C35 -> Process Optimization | C48: ='Project Management Data'!E35 -> 45294 | D48: ='Project Management Data'!F35 -> 30
B49: ='Project Management Data'!C44 -> Event Planning | C49: ='Project Management Data'!E44 -> 45294 | D49: ='Project Management Data'!F44 -> 25
B50: ='Project Management Data'!C47 -> Supply Chain Management | C50: ='Project Management Data'!E47 -> 45294 | D50: ='Project Management Data'!F47 -> 25
...

Sheet Project Management Data
B2: Excel Sample Data
B4: Project Management Data
B6: Project Name | C6: Task Name | D6: Assigned to | E6: Start Date | F6: Days Required | G6: End Date | H6: Progress
B7: Marketing | C7: Market Research | D7: Alice | E7: 45292 | F7: 13 | G7: 45305 | H7: 0.78
B8: Marketing | C8: Content Creation | D8: Bob | E8: 45305 | F8: 14 | G8: 45319 | H8: 1
B9: Marketing | C9: Social Media Planning | D9: Charlie | E9: 45319 | F9: 22 | G9: 45341 | H9: 0.45
B10: Marketing | C10: Campaign Analysis | D10: Daisy | E10: 45340 | F10: 25 | G10: 45365 | H10: 0
B11: Product Dev | C11: Prototype Development | D11: Ethan | E11: 45293 | F11: 18 | G11: 45311 | H11: 1
B12: Product Dev | C12: Quality Assurance | D12: Fiona | E12: 45311 | F12: 10 | G12: 45321 | H12: 0.78
B13: Product Dev | C13: User Interface Design | D13: Gabriel | E13: 45326 | F13: 25 | G13: 45351 | H13: 0
B14: Customer Svc | C14: Service Improvement | D14: Hannah | E14: 45323 | F14: 22 | G14: 45345 | H14: 1
B15: Customer Svc | C15: Ticket Resolution | D15: Ian | E15: 45346 | F15: 25 | G15: 45371 | H15: 1
B16: Customer Svc | C16: Customer Feedback | D16: Julia | E16: 45372 | F16: 30 | G16: 45402 | H16: 0
B17: Financial | C17: Budget Analysis | D17: Kevin | E17: 45324 | F17: 22 | G17: 45346 | H17: 0.1
B18: Financial | C18: Financial Reporting | D18: Mark | E18: 45335 | F18: 21 | G18: 45331 | H18: 0.78
... B52: Engineering | C52: Prototype Testing | D52: Tom | E52: 45345 | F52: 27 | G52: 45372 | H52: 0
